Workbook

Sheet Original Data
A1: store_id | B1: month | C1: region | D1: store_type | E1: marketing_spend | F1: footfall | G1: avg_discount_pct | H1: staff_count | I1: inventory_availability_pct | J1: competitor_distance_km | K1: holiday_flag | L1: customer_rating | M1: monthly_sales | N1: monthly_profit
A2: STR-1001 | B2: 45658 | C2: East | D2: Residential | E2: 70389.11 | F2: 8302 | G2: 0.042 | H2: 17 | I2: 75 | J2: 5.28 | K2: 1 | L2: 3.1 | M2: 658832.62 | N2: 84349.93
A3: STR-1001 | B3: 45689 | C3: East | D3: Residential | E3: 43827.89 | F3: 8487 | G3: 0.168 | H3: 23 | I3: 84.4 | J3: 4.31 | K3: 0 | L3: 2.8 | M3: 634436 | N3: 106130.54
A4: STR-1001 | B4: 45717 | C4: East | D4: Residential | E4: 59921.75 | F4: 9113 | G4: 0.133 | H4: 20 | I4: 88 | J4: 12 | K4: 0 | L4: 3.2 | M4: 678722.06 | N4: 101883.86
A5: STR-1001 | B5: 45748 | C5: East | D5: Residential | E5: 56856.63 | F5: 9431 | G5: 0.142 | H5: 23 | I5: 86.9 | J5: 4.97 | K5: 0 | L5: 3.4 | M5: 658920.3 | N5: 97910.37
A6: STR-1002 | B6: 45658 | C6: East | D6: High Street | E6: 48412.64 | F6: 9545 | G6: 0.231 | H6: 21 | I6: 97.6 | J6: 6.94 | K6: 1 | L6: 4.2 | M6: 741341.44 | N6: 119208.17
A7: STR-1002 | B7: 45689 | C7: East | D7: High Street | E7: 64811.21 | F7: 9792 | G7: 0.112 | H7: 20 | I7: 84.2 | J7: 2.88 | K7: 0 | L7: 4.2 | M7: 761835.34 | N7: 149602.23
A8: STR-1002 | B8: 45717 | C8: East | D8: High Street | E8: 46213.45 | F8: 10616 | G8: 0.122 | H8: 22 | I8: 85.2 | J8: 0.2 | K8: 1 | L8: 4.1 | M8: 806615.54 | N8: 131364.62
A9: STR-1002 | B9: 45748 | C9: East | D9: High Street | E9: 68148.52 | F9: 8567 | G9: 0.127 | H9: 23 | I9: 95.6 | J9: 0.8 | K9: 0 | L9: 3.9 | M9: 850164.26 | N9: 149262.75
A10: STR-1003 | B10: 45658 | C10: North | D10: Airport | E10: 71838.86 | F10: 10979 | G10: 0.215 | H10: 26 | I10: 88.6 | J10: 7.7 | K10: 1 | L10: 3.8 | M10: 930581.7 | N10: 136207.98
A11: STR-1003 | B11: 45689 | C11: North | D11: Airport | E11: 68133.44 | F11: 9459 | G11: 0.22 | H11: 21 | I11: 85 | J11: 1.91 | K11: 0 | L11: 4.2 | M11: 779010.94 | N11: 106328.09
A12: STR-1003 | B12: 45717 | C12: North | D12: Airport | E12: 34285.21 | F12: 9172 | G12: 0.213 | H12: 22 | I12: 88.3 | J12: 10.46 | K12: 1 | L12: 3.8 | M12: 723060.76 | N12: 123131.24
A13: STR-1003 | B13: 45748 | C13: North | D13: Airport | E13: 67979.88 | F13: 11230 | G13: 0.002 | H13: 28 | I13: 85.3 | J13: 7.16 | K13: 0 | L13: 3.8 | M13: 910791.94 | N13: 158891.28
... A34: STR-1009 | B34: 45658 | C34: North | D34: Residential | E34: 54597.83 | F34: 9429 | G34: 0.188 | H34: 21 | I34: 83.3 | J34: 11.71 | K34: 0 | L34: 4.2 | M34: 641865.03 | N34: 81342.58
A35: STR-1009 | B35: 45689 | C35: North | D35: Residential | E35: 73771.91 | F35: 11695 | G35: 0.07 | H35: 25 | I35: 84.7 | J35: 0.62 | K35: 0 | M35: 799477.76 | N35: 164974.41
A36: STR-1009 | B36: 45717 | C36: North | D36: Residential | E36: 74413.88 | F36: 9449 | G36: 0.039 | H36: 23 | I36: 92.1 | J36: 2.12 | K36: 0 | L36: 3.5 | M36: 798952.17 | N36: 161499.04
A37: STR-1009 | B37: 45748 | C37: North | D37: Residential | E37: 52483.77 | F37: 10453 | G37: 0.247 | H37: 25 | I37: 99 | J37: 6.31 | K37: 0 | L37: 3.6 | M37: 800979.78 | N37: 149242.27
A38: STR-1010 | B38: 45658 | C38: North | D38: Mall | E38: 75269.87 | F38: 8838 | G38: 0.092 | H38: 21 | I38: 83.1 | J38: 9.56 | K38: 1 | L38: 4.2 | M38: 820593.93 | N38: 115860.06
A39: STR-1010 | B39: 45689 | C39: North | D39: Mall | E39: 61245.41 | F39: 8156 | G39: 0.156 | H39: 19 | I39: 92.9 | J39: 9.05 | K39: 0 | L39: 3.8 | M39: 718330.53 | N39: 93247.9
A40: STR-1010 | B40: 45717 | C40: North | D40: Mall | E40: 93381.26 | F40: 7562 | G40: 0.198 | H40: 19 | I40: 82.9 | J40: 5.05 | K40: 0 | L40: 4 | M40: 736633.4 | N40: 115654.66
A41: STR-1010 | B41: 45748 | C41: North | D41: Mall | E41: 65012.19 | F41: 9598 | G41: 0.085 | H41: 24 | I41: 98.3 | J41: 0.89 | K41: 0 | L41: 3.8 | M41: 828623.85 | N41: 167320.52
A42: STR-1011 | B42: 45658 | C42: East | D42: Mall | E42: 40462.94 | F42: 3660 | G42: 0.218 | H42: 11 | I42: 95.2 | J42: 5.57 | K42: 0 | L42: 4.4 | M42: 592195.85 | N42: 92291.56
A43: STR-1011 | B43: 45689 | C43: East | D43: Mall | E43: 46123.88 | F43: 3227 | G43: 0.143 | H43: 10 | I43: 75.4 | J43: 1.06 | K43: 0 | L43: 4.4 | M43: 532644.46 | N43: 60681.32
A44: STR-1011 | B44: 45717 | C44: East | D44: Mall | E44: 68077.54 | F44: 3360 | G44: 0.128 | H44: 14 | I44: 88.2 | J44: 1.24 | K44: 1 | L44: 4 | M44: 657429.18 | N44: 88919.74
A45: STR-1011 | B45: 45748 | C45: East | D45: Mall | E45: 64882.14 | F45: 3642 | G45: 0.019 | H45: 13 | I45: 87.8 | J45: 4.52 | K45: 0 | L45: 4.2 | M45: 605178 | N45: 106958.74
A46: STR-1012 | B46: 45658 | C46: West | D46: Residential | E46: 138855.51 | F46: 5145 | G46: 0.06 | H46: 17 | I46: 88.2 | J46: 9.58 | K46: 0 | L46: 3.2 | M46: 595467.6 | N46: 104276.46
A47: STR-1012 | B47: 45689 | C47: West | D47: Residential | E47: 63630.21 | F47: 4460 | G47: 0.235 | H47: 14 | I47: 98.6 | J47: 5.52 | K47: 0 | L47: 3.5 | M47: 599603.4 | N47: 112685.12
... A72: STR-1018 | B72: 45717 | C72: East | D72: High Street | E72: 60571.82 | F72: 3193 | G72: 0.197 | H72: 7 | I72: 99 | J72: 1.43 | K72: 0 | L72: 3.2 | M72: 605023.87 | N72: 98545.81
A73: STR-1018 | B73: 45748 | C73: East | D73: High Street | E73: 55081.16 | F73: 5485 | G73: 0.036 | H73: 12 | I73: 88 | K73: 0 | L73: 3.5 | M73: 674774.09 | N73: 141917.59
A74: STR-1019 | B74: 45658 | C74: East | D74: Residential | E74: 46201.46 | F74: 5918 | G74: 0.277 | H74: 13 | I74: 78.8 | J74: 4.91 | K74: 0 | L74: 4.5 | M74: 616069.41 | N74: 54453.99
A75: STR-1019 | B75: 45689 | C75: East | D75: Residential | E75: 53762.92 | F75: 6821 | G75: 0.066 | H75: 19 | I75: 94.6 | J75: 7.03 | K75: 0 | L75: 4.4 | M75: 630829.94 | N75: 117090.02
A76: STR-1019 | B76: 45717 | C76: East | D76: Residential | E76: 70144.78 | F76: 6806 | G76: 0.178 | H76: 20 | I76: 93.1 | J76: 0.28 | K76: 1 | L76: 4.3 | M76: 788087.68 | N76: 116803.42
A77: STR-1019 | B77: 45748 | C77: East | D77: Residential | E77: 58749.63 | F77: 8252 | G77: 0.203 | H77: 20 | I77: 85.2 | J77: 3.61 | K77: 0 | L77: 4.5 | M77: 680840.36 | N77: 68007.68
A78: STR-1020 | B78: 45658 | C78: South | D78: High Street | E78: 56973.18 | F78: 6662 | G78: 0.1 | H78: 15 | I78: 77.7 | J78: 7.52 | K78: 1 | L78: 3.2 | M78: 643657.47 | N78: 87022.45
A79: STR-1020 | B79: 45689 | C79: South | D79: High Street | E79: 54872.82 | F79: 5962 | G79: 0.064 | H79: 12 | I79: 85.4 | J79: 2.58 | K79: 0 | L79: 2.9 | M79: 691112.6 | N79: 109212.83
A80: STR-1020 | B80: 45717 | C80: South | D80: High Street | E80: 80562.81 | F80: 7470 | G80: 0.172 | H80: 16 | I80: 83.5 | J80: 2.29 | K80: 0 | L80: 3.3 | M80: 776922.17 | N80: 150701.93
A81: STR-1020 | B81: 45748 | C81: South | D81: High Street | E81: 77999.9 | F81: 5974 | G81: 0.252 | H81: 14 | I81: 81.3 | J81: 2.39 | K81: 0 | L81: 3.2 | M81: 636561.34 | N81: 93861.06
A82: STR-1021 | B82: 45658 | C82: West | D82: Mall | E82: 60881.01 | F82: 5410 | G82: 0.179 | H82: 15 | I82: 83.9 | J82: 5.24 | K82: 0 | L82: 4.6 | M82: 621369.58 | N82: 85493.64
A83: STR-1021 | B83: 45689 | C83: West | D83: Mall | E83: 60628.38 | F83: 4451 | G83: 0.095 | H83: 10 | I83: 89.6 | J83: 3.17 | K83: 0 | L83: 4.6 | M83: 682208.01 | N83: 110318.84
A84: STR-1021 | B84: 45717 | C84: West | D84: Mall | E84: 72731.14 | F84: 4644 | G84: 0.084 | H84: 15 | I84: 87.1 | J84: 2.66 | K84: 0 | L84: 4.6 | M84: 727241.86 | N84: 155810.3
...

Sheet Cleaned Data
A1: store_id | B1: month | C1: region | D1: store_type | E1: marketing_spend | F1: footfall | G1: avg_discount_pct | H1: staff_count | I1: inventory_availability_pct | J1: competitor_distance_km | K1: holiday_flag | L1: customer_rating | M1: monthly_sales | N1: monthly_profit
A2: STR-1001 | B2: 45658 | C2: East | D2: Residential | E2: 70389.11 | F2: 8302 | G2: 0.042 | H2: 17 | I2: 0.75 | J2: 5.28 | K2: 1 | L2: 3.1 | M2: 658832.62 | N2: 84349.93
A3: STR-1001 | B3: 45689 | C3: East | D3: Residential | E3: 43827.89 | F3: 8487 | G3: 0.168 | H3: 23 | I3: 0.844 | J3: 4.31 | K3: 0 | L3: 2.8 | M3: 634436 | N3: 106130.54
A4: STR-1001 | B4: 45717 | C4: East | D4: Residential | E4: 59921.75 | F4: 9113 | G4: 0.133 | H4: 20 | I4: 0.88 | J4: 12 | K4: 0 | L4: 3.2 | M4: 678722.06 | N4: 101883.86
A5: STR-1001 | B5: 45748 | C5: East | D5: Residential | E5: 56856.63 | F5: 9431 | G5: 0.142 | H5: 23 | I5: 0.869 | J5: 4.97 | K5: 0 | L5: 3.4 | M5: 658920.3 | N5: 97910.37
A6: STR-1002 | B6: 45658 | C6: East | D6: High Street | E6: 48412.64 | F6: 9545 | G6: 0.231 | H6: 21 | I6: 0.976 | J6: 6.94 | K6: 1 | L6: 4.2 | M6: 741341.44 | N6: 119208.17
A7: STR-1002 | B7: 45689 | C7: East | D7: High Street | E7: 64811.21 | F7: 9792 | G7: 0.112 | H7: 20 | I7: 0.842 | J7: 2.88 | K7: 0 | L7: 4.2 | M7: 761835.34 | N7: 149602.23
A8: STR-1002 | B8: 45717 | C8: East | D8: High Street | E8: 46213.45 | F8: 10616 | G8: 0.122 | H8: 22 | I8: 0.852 | J8: 0.2 | K8: 1 | L8: 4.1 | M8: 806615.54 | N8: 131364.62
A9: STR-1002 | B9: 45748 | C9: East | D9: High Street | E9: 68148.52 | F9: 8567 | G9: 0.127 | H9: 23 | I9: 0.956 | J9: 0.8 | K9: 0 | L9: 3.9 | M9: 850164.26 | N9: 149262.75
A10: STR-1003 | B10: 45658 | C10: North | D10: Airport | E10: 71838.86 | F10: 10979 | G10: 0.215 | H10: 26 | I10: 0.886 | J10: 7.7 | K10: 1 | L10: 3.8 | M10: 930581.7 | N10: 136207.98
A11: STR-1003 | B11: 45689 | C11: North | D11: Airport | E11: 68133.44 | F11: 9459 | G11: 0.22 | H11: 21 | I11: 0.85 | J11: 1.91 | K11: 0 | L11: 4.2 | M11: 779010.94 | N11: 106328.09
A12: STR-1003 | B12: 45717 | C12: North | D12: Airport | E12: 34285.21 | F12: 9172 | G12: 0.213 | H12: 22 | I12: 0.883 | J12: 10.46 | K12: 1 | L12: 3.8 | M12: 723060.76 | N12: 123131.24
A13: STR-1003 | B13: 45748 | C13: North | D13: Airport | E13: 67979.88 | F13: 11230 | G13: 0.002 | H13: 28 | I13: 0.853 | J13: 7.16 | K13: 0 | L13: 3.8 | M13: 910791.94 | N13: 158891.28
... A321: STR-1080 | B321: 45748 | C321: East | D321: Residential | E321: 40553.11 | F321: 5317 | G321: 0.165 | H321: 17 | I321: 0.843 | J321: 11.82 | K321: 0 | L321: 4.1 | M321: 559660.84 | N321: 71443.61

Sheet SRMODEL 1
A2: SINGLE REGRESSION MODEL 1: SUMMARY OUTPUT FOR MONTHLY SALES VS MARKETING SPEND
A4: Regression Statistics
A5: Multiple R | B5: 0.40895561 | D5: Regression equation | E5: monthly_sales = 560777.35 + 2.1296 * marketing_spend
A6: R Square | B6: 0.16724469
A7: Adjusted R Square | B7: 0.16462596
A8: Standard Error | B8: 94846.034
A9: Observations | B9: 320
A11: ANOVA
B12: df | C12: SS | D12: MS | E12: F | F12: Significance F
A13: Regression | B13: 1 | C13: 5.7451371e+11 | D13: 5.7451371e+11 | E13: 63.864873 | F13: 2.4800615e-14
A14: Residual | B14: 318 | C14: 2.8606549e+12 | D14: 8.9957701e+09
A15: Total | B15: 319 | C15: 3.4351686e+12
B17: Coefficients | C17: Standard Error | D17: t Stat | E17: P-value | F17: Lower 95% | G17: Upper 95% | H17: Lower 95.0% | I17: Upper 95.0%
A18: Intercept | B18: 560777.35 | C18: 15906.906 | D18: 35.253703 | E18: 6.9528769e-112 | F18: 529481.27 | G18: 592073.42 | H18: 529481.27 | I18: 592073.42
A19: marketing_spend | B19: 2.1295753 | C19: 0.26647838 | D19: 7.9915501 | E19: 2.4800615e-14 | F19: 1.6052919 | G19: 2.6538587 | H19: 1.6052919 | I19: 2.6538587
A22: RESIDUAL OUTPUT
A24: Observation | B24: Predicted monthly_sales | C24: Residuals
A25: 1 | B25: 710676.26 | C25: -51843.637
A26: 2 | B26: 654112.14 | C26: -19676.139
A27: 3 | B27: 688385.23 | C27: -9663.1658
A28: 4 | B28: 681857.82 | C28: -22937.522
A29: 5 | B29: 663875.71 | C29: 77465.731
A30: 6 | B30: 698797.7 | C30: 63037.641
A31: 7 | B31: 659192.37 | C31: 147423.17
A32: 8 | B32: 705904.75 | C32: 144259.51
A33: 9 | B33: 713763.61 | C33: 216818.09
A34: 10 | B34: 705872.64 | C34: 73138.302
A35: 11 | B35: 633790.28 | C35: 89270.477
A36: 12 | B36: 705545.62 | C36: 205246.32
... A344: 320 | B344: 647138.25 | C344: -87477.408

Sheet SRMODEL 2
A1: SINGLE REGRESSION MODEL 2: SUMMARY OUTPUT MONTHLY SALES VS FOOTFALL
A3: Regression Statistics | D3: regression formula | E3: monthly_sales = 446410.58 + 35.6780 * footfall
A4: Multiple R | B4: 0.85807071
A5: R Square | B5: 0.73628534
A6: Adjusted R Square | B6: 0.73545605
A7: Standard Error | B7: 53373.736
A8: Observations | B8: 320
A10: ANOVA
B11: df | C11: SS | D11: MS | E11: F | F11: Significance F
A12: Regression | B12: 1 | C12: 2.5292643e+12 | D12: 2.5292643e+12 | E12: 887.84878 | F12: 4.7503615e-94
A13: Residual | B13: 318 | C13: 9.0590432e+11 | D13: 2.8487557e+09
A14: Total | B14: 319 | C14: 3.4351686e+12
B16: Coefficients | C16: Standard Error | D16: t Stat | E16: P-value | F16: Lower 95% | G16: Upper 95% | H16: Lower 95.0% | I16: Upper 95.0%
A17: Intercept | B17: 446410.58 | C17: 8407.7383 | D17: 53.095205 | E17: 4.0862696e-160 | F17: 429868.76 | G17: 462952.4 | H17: 429868.76 | I17: 462952.4
A18: footfall | B18: 35.678031 | C18: 1.1973783 | D18: 29.796791 | E18: 4.7503615e-94 | F18: 33.322247 | G18: 38.033815 | H18: 33.322247 | I18: 38.033815
A22: RESIDUAL OUTPUT
A24: Observation | B24: Predicted monthly_sales | C24: Residuals
A25: 1 | B25: 742609.6 | C25: -83776.977
A26: 2 | B26: 749210.03 | C26: -114774.03
A27: 3 | B27: 771544.48 | C27: -92822.42
A28: 4 | B28: 782890.09 | C28: -123969.79
A29: 5 | B29: 786957.39 | C29: -45615.95
A30: 6 | B30: 795769.86 | C30: -33934.523
A31: 7 | B31: 825168.56 | C31: -18553.021
A32: 8 | B32: 752064.28 | C32: 98099.985
A33: 9 | B33: 838119.69 | C33: 92462.014
A34: 10 | B34: 783889.08 | C34: -4878.1389
A35: 11 | B35: 773649.48 | C35: -50588.724
A36: 12 | B36: 847074.87 | C36: 63717.068
... A344: 320 | B344: 636110.67 | C344: -76449.834

Sheet MR Input
A1: store_id | B1: month | C1: monthly_sales | D1: marketing_spend | E1: footfall | F1: avg_discount_pct | G1: inventory_availability_pct | H1: customer_rating | I1: reg_West | J1: reg_North | K1: reg_South | L1: type_HighStreet | M1: type_Residential | N1: type_Airport
A2: STR-1001 | B2: 45658 | C2: 658832.62 | D2: 70389.11 | E2: 8302 | F2: 0.042 | G2: 0.75 | H2: 3.1 | I2: 0 | J2: 0 | K2: 0 | L2: 0 | M2: 1 | N2: 0
A3: STR-1001 | B3: 45689 | C3: 634436 | D3: 43827.89 | E3: 8487 | F3: 0.168 | G3: 0.844 | H3: 2.8 | I3: 0 | J3: 0 | K3: 0 | L3: 0 | M3: 1 | N3: 0
A4: STR-1001 | B4: 45717 | C4: 678722.06 | D4: 59921.75 | E4: 9113 | F4: 0.133 | G4: 0.88 | H4: 3.2 | I4: 0 | J4: 0 | K4: 0 | L4: 0 | M4: 1 | N4: 0
A5: STR-1001 | B5: 45748 | C5: 658920.3 | D5: 56856.63 | E5: 9431 | F5: 0.142 | G5: 0.869 | H5: 3.4 | I5: 0 | J5: 0 | K5: 0 | L5: 0 | M5: 1 | N5: 0
A6: STR-1002 | B6: 45658 | C6: 741341.44 | D6: 48412.64 | E6: 9545 | F6: 0.231 | G6: 0.976 | H6: 4.2 | I6: 0 | J6: 0 | K6: 0 | L6: 1 | M6: 0 | N6: 0
A7: STR-1002 | B7: 45689 | C7: 761835.34 | D7: 64811.21 | E7: 9792 | F7: 0.112 | G7: 0.842 | H7: 4.2 | I7: 0 | J7: 0 | K7: 0 | L7: 1 | M7: 0 | N7: 0
A8: STR-1002 | B8: 45717 | C8: 806615.54 | D8: 46213.45 | E8: 10616 | F8: 0.122 | G8: 0.852 | H8: 4.1 | I8: 0 | J8: 0 | K8: 0 | L8: 1 | M8: 0 | N8: 0
A9: STR-1002 | B9: 45748 | C9: 850164.26 | D9: 68148.52 | E9: 8567 | F9: 0.127 | G9: 0.956 | H9: 3.9 | I9: 0 | J9: 0 | K9: 0 | L9: 1 | M9: 0 | N9: 0
A10: STR-1003 | B10: 45658 | C10: 930581.7 | D10: 71838.86 | E10: 10979 | F10: 0.215 | G10: 0.886 | H10: 3.8 | I10: 0 | J10: 1 | K10: 0 | L10: 0 | M10: 0 | N10: 1
A11: STR-1003 | B11: 45689 | C11: 779010.94 | D11: 68133.44 | E11: 9459 | F11: 0.22 | G11: 0.85 | H11: 4.2 | I11: 0 | J11: 1 | K11: 0 | L11: 0 | M11: 0 | N11: 1
A12: STR-1003 | B12: 45717 | C12: 723060.76 | D12: 34285.21 | E12: 9172 | F12: 0.213 | G12: 0.883 | H12: 3.8 | I12: 0 | J12: 1 | K12: 0 | L12: 0 | M12: 0 | N12: 1
A13: STR-1003 | B13: 45748 | C13: 910791.94 | D13: 67979.88 | E13: 11230 | F13: 0.002 | G13: 0.853 | H13: 3.8 | I13: 0 | J13: 1 | K13: 0 | L13: 0 | M13: 0 | N13: 1
... A321: STR-1080 | B321: 45748 | C321: 559660.84 | D321: 40553.11 | E321: 5317 | F321: 0.165 | G321: 0.843 | H321: 4.1 | I321: 0 | J321: 0 | K321: 0 | L321: 0 | M321: 1 | N321: 0

Sheet MR Output
A1: SUMMARY OUTPUT FOR MUTLIPLE REGRESSION AGAINST MONTHLY SALES
A3: Regression Statistics
A4: Multiple R | B4: 0.91214842 | D4: regression equation | E4: monthly_sales = 79,339.71 + 1.2002(marketing_spend) + 34.0035(footfall) − 457.3614(avg_discount_pct_pct) + 300,179.63(inventory_availability_decimal) + 13,548.49(customer_rating) + 6,184.86(region_North) + 18,676.80(region_South) + 18,109.76(region_West) + 12,784.08(type_Airport) − 11,004.46(type_HighStreet) − 29,093.02(type_Residential)
A5: R Square | B5: 0.83201474
A6: Adjusted R Square | B6: 0.82601527
A7: Standard Error | B7: 43284.685
A8: Observations | B8: 320
A10: ANOVA
B11: df | C11: SS | D11: MS | E11: F | F11: Significance F
A12: Regression | B12: 11 | C12: 2.8581109e+12 | D12: 2.5982827e+11 | E12: 138.68129 | F12: 3.1218576e-112
A13: Residual | B13: 308 | C13: 5.7705769e+11 | D13: 1.8735639e+09
A14: Total | B14: 319 | C14: 3.4351686e+12
B16: Coefficients | C16: Standard Error | D16: t Stat | E16: P-value | F16: Lower 95% | G16: Upper 95% | H16: Lower 95.0% | I16: Upper 95.0%
A17: Intercept | B17: 79274.518 | C17: 47721.302 | D17: 1.6611977 | E17: 0.097691265 | F17: -14626.498 | G17: 173175.53 | H17: -14626.498 | I17: 173175.53
A18: marketing_spend | B18: 1.2002715 | C18: 0.12573133 | D18: 9.5463196 | E18: 4.3475726e-19 | F18: 0.95287044 | G18: 1.4476725 | H18: 0.95287044 | I18: 1.4476725
A19: footfall | B19: 34.003428 | C19: 1.0139044 | D19: 33.537115 | E19: 7.8814927e-105 | F19: 32.008373 | G19: 35.998484 | H19: 32.008373 | I19: 35.998484
A20: avg_discount_pct | B20: -45730.962 | C20: 36449.451 | D20: -1.2546406 | E20: 0.21056047 | F20: -117452.4 | G20: 25990.476 | H20: -117452.4 | I20: 25990.476
A21: inventory_availability_pct | B21: 300183.43 | C21: 45818.217 | D21: 6.5516175 | E21: 2.3883322e-10 | F21: 210027.11 | G21: 390339.75 | H21: 210027.11 | I21: 390339.75
A22: customer_rating | B22: 13563.576 | C22: 4776.2173 | D22: 2.8398155 | E22: 0.0048143343 | F22: 4165.4321 | G22: 22961.72 | H22: 4165.4321 | I22: 22961.72
A23: reg_West | B23: 18109.962 | C23: 6254.4007 | D23: 2.8955551 | E23: 0.0040555709 | F23: 5803.2025 | G23: 30416.721 | H23: 5803.2025 | I23: 30416.721
A24: reg_North | B24: 6184.7586 | C24: 7031.1951 | D24: 0.87961697 | E24: 0.37975261 | F24: -7650.496 | G24: 20020.013 | H24: -7650.496 | I24: 20020.013
A25: reg_South | B25: 18678.421 | C25: 7140.6777 | D25: 2.6157771 | E25: 0.0093410011 | F25: 4627.7382 | G25: 32729.104 | H25: 4627.7382 | I25: 32729.104
A26: type_HighStreet | B26: -11002.4 | C26: 6487.438 | D26: -1.6959545 | E26: 0.09090496 | F26: -23767.706 | G26: 1762.9059 | H26: -23767.706 | I26: 1762.9059
A27: type_Residential | B27: -29091.732 | C27: 6617.4333 | D27: -4.3962259 | E27: 1.5183081e-05 | F27: -42112.829 | G27: -16070.635 | H27: -42112.829 | I27: -16070.635
A28: type_Airport | B28: 12786.004 | C28: 9666.7455 | D28: 1.3226792 | E28: 0.18692331 | F28: -6235.2129 | G28: 31807.22 | H28: -6235.2129 | I28: 31807.22
A32: RESIDUAL OUTPUT
A34: Observation | B34: Predicted monthly_sales | C34: Residuals
A35: 1 | B35: 682229.25 | C35: -23396.627
A36: 2 | B36: 675025.27 | C36: -40589.275
A37: 3 | B37: 733461.04 | C37: -54738.979
A38: 4 | B38: 739594.27 | C38: -80673.972
A39: 5 | B39: 790325.35 | C39: -48983.907
A40: 6 | B40: 783624.33 | C40: -21788.994
A41: 7 | B41: 790508.97 | C41: 16106.574
A42: 8 | B42: 775441.69 | C42: 74722.574
A43: 9 | B43: 865467.01 | C43: 65114.695
A44: 10 | B44: 803724.46 | C44: -24713.516
A45: 11 | B45: 758139.15 | C45: -35078.387
A46: 12 | B46: 869204.68 | C46: 41587.256
... A354: 320 | B354: 580773.44 | C354: -21112.6

Sheet Dummy Variables
A1: store_id | B1: month | C1: reg_West | D1: reg_North | E1: reg_South | F1: type_HighStreet | G1: type_Residential | H1: type_Airport
A2: ='Cleaned Data'!A2 -> STR-1001 | B2: ='Cleaned Data'!B2 -> 45658 | C2: =IF('Cleaned Data'!C2="West", 1, 0) -> 0 | D2: =IF('Cleaned Data'!C2="North", 1, 0) -> 0 | E2: =IF('Cleaned Data'!C2="South", 1, 0) -> 0 | F2: =IF('Cleaned Data'!D2="High Street", 1, 0) -> 0 | G2: =IF('Cleaned Data'!D2="Residential", 1, 0) -> 1 | H2: =IF('Cleaned Data'!D2="Airport", 1, 0) -> 0
A3: ='Cleaned Data'!A3 -> STR-1001 | B3: ='Cleaned Data'!B3 -> 45689 | C3: =IF('Cleaned Data'!C3="West", 1, 0) -> 0 | D3: =IF('Cleaned Data'!C3="North", 1, 0) -> 0 | E3: =IF('Cleaned Data'!C3="South", 1, 0) -> 0 | F3: =IF('Cleaned Data'!D3="High Street", 1, 0) -> 0 | G3: =IF('Cleaned Data'!D3="Residential", 1, 0) -> 1 | H3: =IF('Cleaned Data'!D3="Airport", 1, 0) -> 0
A4: ='Cleaned Data'!A4 -> STR-1001 | B4: ='Cleaned Data'!B4 -> 45717 | C4: =IF('Cleaned Data'!C4="West", 1, 0) -> 0 | D4: =IF('Cleaned Data'!C4="North", 1, 0) -> 0 | E4: =IF('Cleaned Data'!C4="South", 1, 0) -> 0 | F4: =IF('Cleaned Data'!D4="High Street", 1, 0) -> 0 | G4: =IF('Cleaned Data'!D4="Residential", 1, 0) -> 1 | H4: =IF('Cleaned Data'!D4="Airport", 1, 0) -> 0
A5: ='Cleaned Data'!A5 -> STR-1001 | B5: ='Cleaned Data'!B5 -> 45748 | C5: =IF('Cleaned Data'!C5="West", 1, 0) -> 0 | D5: =IF('Cleaned Data'!C5="North", 1, 0) -> 0 | E5: =IF('Cleaned Data'!C5="South", 1, 0) -> 0 | F5: =IF('Cleaned Data'!D5="High Street", 1, 0) -> 0 | G5: =IF('Cleaned Data'!D5="Residential", 1, 0) -> 1 | H5: =IF('Cleaned Data'!D5="Airport", 1, 0) -> 0
A6: ='Cleaned Data'!A6 -> STR-1002 | B6: ='Cleaned Data'!B6 -> 45658 | C6: =IF('Cleaned Data'!C6="West", 1, 0) -> 0 | D6: =IF('Cleaned Data'!C6="North", 1, 0) -> 0 | E6: =IF('Cleaned Data'!C6="South", 1, 0) -> 0 | F6: =IF('Cleaned Data'!D6="High Street", 1, 0) -> 1 | G6: =IF('Cleaned Data'!D6="Residential", 1, 0) -> 0 | H6: =IF('Cleaned Data'!D6="Airport", 1, 0) -> 0
A7: ='Cleaned Data'!A7 -> STR-1002 | B7: ='Cleaned Data'!B7 -> 45689 | C7: =IF('Cleaned Data'!C7="West", 1, 0) -> 0 | D7: =IF('Cleaned Data'!C7="North", 1, 0) -> 0 | E7: =IF('Cleaned Data'!C7="South", 1, 0) -> 0 | F7: =IF('Cleaned Data'!D7="High Street", 1, 0) -> 1 | G7: =IF('Cleaned Data'!D7="Residential", 1, 0) -> 0 | H7: =IF('Cleaned Data'!D7="Airport", 1, 0) -> 0
A8: ='Cleaned Data'!A8 -> STR-1002 | B8: ='Cleaned Data'!B8 -> 45717 | C8: =IF('Cleaned Data'!C8="West", 1, 0) -> 0 | D8: =IF('Cleaned Data'!C8="North", 1, 0) -> 0 | E8: =IF('Cleaned Data'!C8="South", 1, 0) -> 0 | F8: =IF('Cleaned Data'!D8="High Street", 1, 0) -> 1 | G8: =IF('Cleaned Data'!D8="Residential", 1, 0) -> 0 | H8: =IF('Cleaned Data'!D8="Airport", 1, 0) -> 0
A9: ='Cleaned Data'!A9 -> STR-1002 | B9: ='Cleaned Data'!B9 -> 45748 | C9: =IF('Cleaned Data'!C9="West", 1, 0) -> 0 | D9: =IF('Cleaned Data'!C9="North", 1, 0) -> 0 | E9: =IF('Cleaned Data'!C9="South", 1, 0) -> 0 | F9: =IF('Cleaned Data'!D9="High Street", 1, 0) -> 1 | G9: =IF('Cleaned Data'!D9="Residential", 1, 0) -> 0 | H9: =IF('Cleaned Data'!D9="Airport", 1, 0) -> 0
A10: ='Cleaned Data'!A10 -> STR-1003 | B10: ='Cleaned Data'!B10 -> 45658 | C10: =IF('Cleaned Data'!C10="West", 1, 0) -> 0 | D10: =IF('Cleaned Data'!C10="North", 1, 0) -> 1 | E10: =IF('Cleaned Data'!C10="South", 1, 0) -> 0 | F10: =IF('Cleaned Data'!D10="High Street", 1, 0) -> 0 | G10: =IF('Cleaned Data'!D10="Residential", 1, 0) -> 0 | H10: =IF('Cleaned Data'!D10="Airport", 1, 0) -> 1
A11: ='Cleaned Data'!A11 -> STR-1003 | B11: ='Cleaned Data'!B11 -> 45689 | C11: =IF('Cleaned Data'!C11="West", 1, 0) -> 0 | D11: =IF('Cleaned Data'!C11="North", 1, 0) -> 1 | E11: =IF('Cleaned Data'!C11="South", 1, 0) -> 0 | F11: =IF('Cleaned Data'!D11="High Street", 1, 0) -> 0 | G11: =IF('Cleaned Data'!D11="Residential", 1, 0) -> 0 | H11: =IF('Cleaned Data'!D11="Airport", 1, 0) -> 1
A12: ='Cleaned Data'!A12 -> STR-1003 | B12: ='Cleaned Data'!B12 -> 45717 | C12: =IF('Cleaned Data'!C12="West", 1, 0) -> 0 | D12: =IF('Cleaned Data'!C12="North", 1, 0) -> 1 | E12: =IF('Cleaned Data'!C12="South", 1, 0) -> 0 | F12: =IF('Cleaned Data'!D12="High Street", 1, 0) -> 0 | G12: =IF('Cleaned Data'!D12="Residential", 1, 0) -> 0 | H12: =IF('Cleaned Data'!D12="Airport", 1, 0) -> 1
A13: ='Cleaned Data'!A13 -> STR-1003 | B13: ='Cleaned Data'!B13 -> 45748 | C13: =IF('Cleaned Data'!C13="West", 1, 0) -> 0 | D13: =IF('Cleaned Data'!C13="North", 1, 0) -> 1 | E13: =IF('Cleaned Data'!C13="South", 1, 0) -> 0 | F13: =IF('Cleaned Data'!D13="High Street", 1, 0) -> 0 | G13: =IF('Cleaned Data'!D13="Residential", 1, 0) -> 0 | H13: =IF('Cleaned Data'!D13="Airport", 1, 0) -> 1
... A321: ='Cleaned Data'!A321 -> STR-1080 | B321: ='Cleaned Data'!B321 -> 45748 | C321: =IF('Cleaned Data'!C321="West", 1, 0) -> 0 | D321: =IF('Cleaned Data'!C321="North", 1, 0) -> 0 | E321: =IF('Cleaned Data'!C321="South", 1, 0) -> 0 | F321: =IF('Cleaned Data'!D321="High Street", 1, 0) -> 0 | G321: =IF('Cleaned Data'!D321="Residential", 1, 0) -> 1 | H321: =IF('Cleaned Data'!D321="Airport", 1, 0) -> 0

Sheet data_dictionary
B1: Description
A2: store_id | B2: Unique store identifier.
A3: month | B3: Reporting month.
A4: region | B4: Business region.
A5: store_type | B5: Mall, High Street, Residential, or Airport.
A6: marketing_spend | B6: Monthly marketing spend for the store.
A7: footfall | B7: Monthly visitor count.
A8: avg_discount_pct | B8: Average discount percentage for the month.
A9: staff_count | B9: Number of store staff.
A10: inventory_availability_pct | B10: Average product availability percentage.
A11: competitor_distance_km | B11: Distance to nearest competitor.
A12: holiday_flag | B12: 1 if the month/store period had a meaningful holiday effect; otherwise 0.
A13: customer_rating | B13: Average customer rating.
... A15: monthly_profit | B15: Optional secondary business metric.
